2023-11-07 11:17 ERROR Traceback (most recent call last):
  File "c:\Users\user\Desktop\程式專區\CpTrader\CpTrader\Database\SQL_operate.py", line 45, in read_Dateframe
    self.userconn = router.Router().mysql_conn
  File "c:\Users\user\Desktop\程式專區\CpTrader\CpTrader\Database\router.py", line 13, in __init__
    self._mysql_conn = self.get_mysql_conn()
  File "c:\Users\user\Desktop\程式專區\CpTrader\CpTrader\Database\router.py", line 28, in get_mysql_conn
    connect = engine.connect()
  File "C:\Users\user\Desktop\程式專區\CpTrader\lib\site-packages\sqlalchemy\engine\base.py", line 3268, in connect
    return self._connection_cls(self)
  File "C:\Users\user\Desktop\程式專區\CpTrader\lib\site-packages\sqlalchemy\engine\base.py", line 145, in __init__
    self._dbapi_connection = engine.raw_connection()
  File "C:\Users\user\Desktop\程式專區\CpTrader\lib\site-packages\sqlalchemy\engine\base.py", line 3292, in raw_connection
    return self.pool.connect()
  File "C:\Users\user\Desktop\程式專區\CpTrader\lib\site-packages\sqlalchemy\pool\base.py", line 452, in connect
    return _ConnectionFairy._checkout(self)
  File "C:\Users\user\Desktop\程式專區\CpTrader\lib\site-packages\sqlalchemy\pool\base.py", line 1269, in _checkout
    fairy = _ConnectionRecord.checkout(pool)
  File "C:\Users\user\Desktop\程式專區\CpTrader\lib\site-packages\sqlalchemy\pool\base.py", line 716, in checkout
    rec = pool._do_get()
  File "C:\Users\user\Desktop\程式專區\CpTrader\lib\site-packages\sqlalchemy\pool\impl.py", line 170, in _do_get
    self._dec_overflow()
  File "C:\Users\user\Desktop\程式專區\CpTrader\lib\site-packages\sqlalchemy\util\langhelpers.py", line 146, in __exit__
    raise exc_value.with_traceback(exc_tb)
  File "C:\Users\user\Desktop\程式專區\CpTrader\lib\site-packages\sqlalchemy\pool\impl.py", line 167, in _do_get
    return self._create_connection()
  File "C:\Users\user\Desktop\程式專區\CpTrader\lib\site-packages\sqlalchemy\pool\base.py", line 393, in _create_connection
    return _ConnectionRecord(self)
  File "C:\Users\user\Desktop\程式專區\CpTrader\lib\site-packages\sqlalchemy\pool\base.py", line 678, in __init__
    self.__connect()
  File "C:\Users\user\Desktop\程式專區\CpTrader\lib\site-packages\sqlalchemy\pool\base.py", line 903, in __connect
    pool.logger.debug("Error on connect(): %s", e)
  File "C:\Users\user\Desktop\程式專區\CpTrader\lib\site-packages\sqlalchemy\util\langhelpers.py", line 146, in __exit__
    raise exc_value.with_traceback(exc_tb)
  File "C:\Users\user\Desktop\程式專區\CpTrader\lib\site-packages\sqlalchemy\pool\base.py", line 898, in __connect
    self.dbapi_connection = connection = pool._invoke_creator(self)
  File "C:\Users\user\Desktop\程式專區\CpTrader\lib\site-packages\sqlalchemy\engine\create.py", line 637, in connect
    return dialect.connect(*cargs, **cparams)
  File "C:\Users\user\Desktop\程式專區\CpTrader\lib\site-packages\sqlalchemy\engine\default.py", line 616, in connect
    return self.loaded_dbapi.connect(*cargs, **cparams)
  File "C:\Users\user\Desktop\程式專區\CpTrader\lib\site-packages\pymysql\connections.py", line 358, in __init__
    self.connect()
  File "C:\Users\user\Desktop\程式專區\CpTrader\lib\site-packages\pymysql\connections.py", line 664, in connect
    self._request_authentication()
  File "C:\Users\user\Desktop\程式專區\CpTrader\lib\site-packages\pymysql\connections.py", line 976, in _request_authentication
    auth_packet = _auth.caching_sha2_password_auth(self, auth_packet)
  File "C:\Users\user\Desktop\程式專區\CpTrader\lib\site-packages\pymysql\_auth.py", line 266, in caching_sha2_password_auth
    data = sha2_rsa_encrypt(conn.password, conn.salt, conn.server_public_key)
  File "C:\Users\user\Desktop\程式專區\CpTrader\lib\site-packages\pymysql\_auth.py", line 143, in sha2_rsa_encrypt
    raise RuntimeError(
RuntimeError: 'cryptography' package is required for sha256_password or caching_sha2_password auth methods

2023-11-07 13:05 ERROR Traceback (most recent call last):
  File "C:\Users\user\Desktop\程式專區\CpTrader\lib\site-packages\sqlalchemy\engine\base.py", line 1969, in _exec_single_context
    self.dialect.do_execute(
  File "C:\Users\user\Desktop\程式專區\CpTrader\lib\site-packages\sqlalchemy\engine\default.py", line 922, in do_execute
    cursor.execute(statement, parameters)
  File "C:\Users\user\Desktop\程式專區\CpTrader\lib\site-packages\pymysql\cursors.py", line 153, in execute
    result = self._query(query)
  File "C:\Users\user\Desktop\程式專區\CpTrader\lib\site-packages\pymysql\cursors.py", line 322, in _query
    conn.query(q)
  File "C:\Users\user\Desktop\程式專區\CpTrader\lib\site-packages\pymysql\connections.py", line 558, in query
    self._affected_rows = self._read_query_result(unbuffered=unbuffered)
  File "C:\Users\user\Desktop\程式專區\CpTrader\lib\site-packages\pymysql\connections.py", line 822, in _read_query_result
    result.read()
  File "C:\Users\user\Desktop\程式專區\CpTrader\lib\site-packages\pymysql\connections.py", line 1200, in read
    first_packet = self.connection._read_packet()
  File "C:\Users\user\Desktop\程式專區\CpTrader\lib\site-packages\pymysql\connections.py", line 772, in _read_packet
    packet.raise_for_error()
  File "C:\Users\user\Desktop\程式專區\CpTrader\lib\site-packages\pymysql\protocol.py", line 221, in raise_for_error
    err.raise_mysql_exception(self._data)
  File "C:\Users\user\Desktop\程式專區\CpTrader\lib\site-packages\pymysql\err.py", line 143, in raise_mysql_exception
    raise errorclass(errno, errval)
pymysql.err.ProgrammingError: (1146, "Table 'crypto_data.slpusdt-f' doesn't exist")

The above exception was the direct cause of the following exception:

Traceback (most recent call last):
  File "c:\Users\user\Desktop\程式專區\CpTrader\CpTrader\Database\SQL_operate.py", line 47, in read_Dateframe
    return pd.read_sql(text_msg, con=conn)
  File "C:\Users\user\Desktop\程式專區\CpTrader\lib\site-packages\pandas\io\sql.py", line 663, in read_sql
    return pandas_sql.read_query(
  File "C:\Users\user\Desktop\程式專區\CpTrader\lib\site-packages\pandas\io\sql.py", line 1738, in read_query
    result = self.execute(sql, params)
  File "C:\Users\user\Desktop\程式專區\CpTrader\lib\site-packages\pandas\io\sql.py", line 1562, in execute
    return self.con.exec_driver_sql(sql, *args)
  File "C:\Users\user\Desktop\程式專區\CpTrader\lib\site-packages\sqlalchemy\engine\base.py", line 1778, in exec_driver_sql
    ret = self._execute_context(
  File "C:\Users\user\Desktop\程式專區\CpTrader\lib\site-packages\sqlalchemy\engine\base.py", line 1848, in _execute_context
    return self._exec_single_context(
  File "C:\Users\user\Desktop\程式專區\CpTrader\lib\site-packages\sqlalchemy\engine\base.py", line 1988, in _exec_single_context
    self._handle_dbapi_exception(
  File "C:\Users\user\Desktop\程式專區\CpTrader\lib\site-packages\sqlalchemy\engine\base.py", line 2343, in _handle_dbapi_exception
    raise sqlalchemy_exception.with_traceback(exc_info[2]) from e
  File "C:\Users\user\Desktop\程式專區\CpTrader\lib\site-packages\sqlalchemy\engine\base.py", line 1969, in _exec_single_context
    self.dialect.do_execute(
  File "C:\Users\user\Desktop\程式專區\CpTrader\lib\site-packages\sqlalchemy\engine\default.py", line 922, in do_execute
    cursor.execute(statement, parameters)
  File "C:\Users\user\Desktop\程式專區\CpTrader\lib\site-packages\pymysql\cursors.py", line 153, in execute
    result = self._query(query)
  File "C:\Users\user\Desktop\程式專區\CpTrader\lib\site-packages\pymysql\cursors.py", line 322, in _query
    conn.query(q)
  File "C:\Users\user\Desktop\程式專區\CpTrader\lib\site-packages\pymysql\connections.py", line 558, in query
    self._affected_rows = self._read_query_result(unbuffered=unbuffered)
  File "C:\Users\user\Desktop\程式專區\CpTrader\lib\site-packages\pymysql\connections.py", line 822, in _read_query_result
    result.read()
  File "C:\Users\user\Desktop\程式專區\CpTrader\lib\site-packages\pymysql\connections.py", line 1200, in read
    first_packet = self.connection._read_packet()
  File "C:\Users\user\Desktop\程式專區\CpTrader\lib\site-packages\pymysql\connections.py", line 772, in _read_packet
    packet.raise_for_error()
  File "C:\Users\user\Desktop\程式專區\CpTrader\lib\site-packages\pymysql\protocol.py", line 221, in raise_for_error
    err.raise_mysql_exception(self._data)
  File "C:\Users\user\Desktop\程式專區\CpTrader\lib\site-packages\pymysql\err.py", line 143, in raise_mysql_exception
    raise errorclass(errno, errval)
sqlalchemy.exc.ProgrammingError: (pymysql.err.ProgrammingError) (1146, "Table 'crypto_data.slpusdt-f' doesn't exist")
[SQL: select Datetime, Open, High, Low, Close, Volume from `slpusdt-f`;]
(Background on this error at: https://sqlalche.me/e/20/f405)

